Workbook
Name _Toc142373946: Funções!$A$10
Name _Toc142373955: Funções!$A$28
Name _Toc199162154: Funções!$O$9
Name TiposDeFuncao: Deflatores!$L$37:$L$64
Name TiposDeManutencao: Deflatores!$G$4:$G$38

Sheet Contagem
A1: Identificação da Contagem
A4: Empresa | F4: Websis | O4: PF IFPUG | Q4: =Funções!L4
A5: Aplicação | F5: =A17 | O5: PF Local do EM | Q5: =Funções!L5
A6: Tipo de Contagem | O6: PF Local da FS | Q6: =Funções!L6
A7: Nível de Detalhe | O7: Tecnologia
A8: Projeto | F8: SENAT | O8: Versão do Guia
A9: Responsável | O9: Criação
A10: Revisor | O10: Revisão
A11: Propósito da Contagem
A12: Estimar o tamanho funcional do projeto conforme NESMA e INMs contratuais.
A16: Escopo da Contagem
A21: Documentação Utilizada na Análise

Sheet Funções
A1: Planilha de contagem de ponto de função - Versão 2.4
A4: =Contagem!A5&" : "&Contagem!F5 | B4: =Contagem!A8&" : "&Contagem!F8 | K4: PF IFPUG | L4: =SUM(H8:H522)
A5: =Contagem!A9&" : "&Contagem!F9 | B5: =Contagem!A10&" : "&Contagem!F10 | K5: PF Local do EM | L5: =SUM(K8:K522)
A6: =Contagem!A4&" : "&Contagem!F4 | B6: ="Tipo da Contagem : "&Contagem!F6 | K6: PF Local da FS | L6: =SUM(L8:L522)
A7: Nome da Função | B7: Tipo | C7: Manutenção | D7: TD | E7: AR/TR | F7: Complex. | G7: ctl | H7: PF IFPUG | I7: C | J7: ctl2 | K7: PF Local do EM | L7: PF Local da FS | M7: Pacote | N7: Referência | O7: Observações
F8: =IF(ISBLANK(B8),"",IF(I8="L","Baixa",IF(I8="A","Média",IF(I8="","","Alta")))) | G8: =CONCATENATE(B8,I8) | H8: =IF(ISBLANK(B8),"",IF(B8="ALI",IF(I8="L",7,IF(I8="A",10,15)),IF(B8="AIE",IF(I8="L",5,IF(I8="A",7,10)),IF(B8="SE",IF(I8="L",4,IF(I8="A",5,7)),IF(OR(B8="EE",B8="CE"),IF(I8="L",3,IF(I8="A",4,6)),0))))) | I8: =IF(OR(ISBLANK(D8),ISBLANK(E8)),IF(OR(B8="ALI",B8="AIE"),"L",IF(OR(B8="EE",B8="SE",B8="CE"),"A","")),IF(B8="EE",IF(E8>=3,IF(D8>=5,"H","A"),IF(E8>=2,IF(D8>=16,"H",IF(D8<=4,"L","A")),IF(D8<=15,"L","A"))),IF(OR(B8="SE",B8="CE"),IF(E8>=4,IF(D8>=6,"H","A"),IF(E8>=2,IF(D8>=20,"H",IF(D8<=5,"L","A")),IF(D8<=19,"L","A"))),IF(OR(B8="ALI",B8="AIE"),IF(E8>=6,IF(D8>=20,"H","A"),IF(E8>=2,IF(D8>=51,"H",IF(D8<=19,"L","A")),IF(D8<=50,"L","A"))),"")))) | J8: =CONCATENATE(B8,C8) | K8: =IF(OR(H8="",H8=0),L8,H8) | L8: =IF(NOT(ISERROR(VLOOKUP(B8,Deflatores!G$42:H$64,2,FALSE))),VLOOKUP(B8,Deflatores!G$42:H$64,2,FALSE),IF(OR(ISBLANK(C8),ISBLANK(B8)),"",VLOOKUP(C8,Deflatores!G$4:H$38,2,FALSE)*H8+VLOOKUP(C8,Deflatores!G$4:I$38,3,FALSE)))
F9: =IF(ISBLANK(B9),"",IF(I9="L","Baixa",IF(I9="A","Média",IF(I9="","","Alta")))) | G9: =CONCATENATE(B9,I9) | H9: =IF(ISBLANK(B9),"",IF(B9="ALI",IF(I9="L",7,IF(I9="A",10,15)),IF(B9="AIE",IF(I9="L",5,IF(I9="A",7,10)),IF(B9="SE",IF(I9="L",4,IF(I9="A",5,7)),IF(OR(B9="EE",B9="CE"),IF(I9="L",3,IF(I9="A",4,6)),0))))) | I9: =IF(OR(ISBLANK(D9),ISBLANK(E9)),IF(OR(B9="ALI",B9="AIE"),"L",IF(OR(B9="EE",B9="SE",B9="CE"),"A","")),IF(B9="EE",IF(E9>=3,IF(D9>=5,"H","A"),IF(E9>=2,IF(D9>=16,"H",IF(D9<=4,"L","A")),IF(D9<=15,"L","A"))),IF(OR(B9="SE",B9="CE"),IF(E9>=4,IF(D9>=6,"H","A"),IF(E9>=2,IF(D9>=20,"H",IF(D9<=5,"L","A")),IF(D9<=19,"L","A"))),IF(OR(B9="ALI",B9="AIE"),IF(E9>=6,IF(D9>=20,"H","A"),IF(E9>=2,IF(D9>=51,"H",IF(D9<=19,"L","A")),IF(D9<=50,"L","A"))),"")))) | J9: =CONCATENATE(B9,C9) | K9: =IF(OR(H9="",H9=0),L9,H9) | L9: =IF(NOT(ISERROR(VLOOKUP(B9,Deflatores!G$42:H$64,2,FALSE))),VLOOKUP(B9,Deflatores!G$42:H$64,2,FALSE),IF(OR(ISBLANK(C9),ISBLANK(B9)),"",VLOOKUP(C9,Deflatores!G$4:H$38,2,FALSE)*H9+VLOOKUP(C9,Deflatores!G$4:I$38,3,FALSE)))
F10: =IF(ISBLANK(B10),"",IF(I10="L","Baixa",IF(I10="A","Média",IF(I10="","","Alta")))) | G10: =CONCATENATE(B10,I10) | H10: =IF(ISBLANK(B10),"",IF(B10="ALI",IF(I10="L",7,IF(I10="A",10,15)),IF(B10="AIE",IF(I10="L",5,IF(I10="A",7,10)),IF(B10="SE",IF(I10="L",4,IF(I10="A",5,7)),IF(OR(B10="EE",B10="CE"),IF(I10="L",3,IF(I10="A",4,6)),0))))) | I10: =IF(OR(ISBLANK(D10),ISBLANK(E10)),IF(OR(B10="ALI",B10="AIE"),"L",IF(OR(B10="EE",B10="SE",B10="CE"),"A","")),IF(B10="EE",IF(E10>=3,IF(D10>=5,"H","A"),IF(E10>=2,IF(D10>=16,"H",IF(D10<=4,"L","A")),IF(D10<=15,"L","A"))),IF(OR(B10="SE",B10="CE"),IF(E10>=4,IF(D10>=6,"H","A"),IF(E10>=2,IF(D10>=20,"H",IF(D10<=5,"L","A")),IF(D10<=19,"L","A"))),IF(OR(B10="ALI",B10="AIE"),IF(E10>=6,IF(D10>=20,"H","A"),IF(E10>=2,IF(D10>=51,"H",IF(D10<=19,"L","A")),IF(D10<=50,"L","A"))),"")))) | J10: =CONCATENATE(B10,C10) | K10: =IF(OR(H10="",H10=0),L10,H10) | L10: =IF(NOT(ISERROR(VLOOKUP(B10,Deflatores!G$42:H$64,2,FALSE))),VLOOKUP(B10,Deflatores!G$42:H$64,2,FALSE),IF(OR(ISBLANK(C10),ISBLANK(B10)),"",VLOOKUP(C10,Deflatores!G$4:H$38,2,FALSE)*H10+VLOOKUP(C10,Deflatores!G$4:I$38,3,FALSE)))
F11: =IF(ISBLANK(B11),"",IF(I11="L","Baixa",IF(I11="A","Média",IF(I11="","","Alta")))) | G11: =CONCATENATE(B11,I11) | H11: =IF(ISBLANK(B11),"",IF(B11="ALI",IF(I11="L",7,IF(I11="A",10,15)),IF(B11="AIE",IF(I11="L",5,IF(I11="A",7,10)),IF(B11="SE",IF(I11="L",4,IF(I11="A",5,7)),IF(OR(B11="EE",B11="CE"),IF(I11="L",3,IF(I11="A",4,6)),0))))) | I11: =IF(OR(ISBLANK(D11),ISBLANK(E11)),IF(OR(B11="ALI",B11="AIE"),"L",IF(OR(B11="EE",B11="SE",B11="CE"),"A","")),IF(B11="EE",IF(E11>=3,IF(D11>=5,"H","A"),IF(E11>=2,IF(D11>=16,"H",IF(D11<=4,"L","A")),IF(D11<=15,"L","A"))),IF(OR(B11="SE",B11="CE"),IF(E11>=4,IF(D11>=6,"H","A"),IF(E11>=2,IF(D11>=20,"H",IF(D11<=5,"L","A")),IF(D11<=19,"L","A"))),IF(OR(B11="ALI",B11="AIE"),IF(E11>=6,IF(D11>=20,"H","A"),IF(E11>=2,IF(D11>=51,"H",IF(D11<=19,"L","A")),IF(D11<=50,"L","A"))),"")))) | J11: =CONCATENATE(B11,C11) | K11: =IF(OR(H11="",H11=0),L11,H11) | L11: =IF(NOT(ISERROR(VLOOKUP(B11,Deflatores!G$42:H$64,2,FALSE))),VLOOKUP(B11,Deflatores!G$42:H$64,2,FALSE),IF(OR(ISBLANK(C11),ISBLANK(B11)),"",VLOOKUP(C11,Deflatores!G$4:H$38,2,FALSE)*H11+VLOOKUP(C11,Deflatores!G$4:I$38,3,FALSE)))
F12: =IF(ISBLANK(B12),"",IF(I12="L","Baixa",IF(I12="A","Média",IF(I12="","","Alta")))) | G12: =CONCATENATE(B12,I12) | H12: =IF(ISBLANK(B12),"",IF(B12="ALI",IF(I12="L",7,IF(I12="A",10,15)),IF(B12="AIE",IF(I12="L",5,IF(I12="A",7,10)),IF(B12="SE",IF(I12="L",4,IF(I12="A",5,7)),IF(OR(B12="EE",B12="CE"),IF(I12="L",3,IF(I12="A",4,6)),0))))) | I12: =IF(OR(ISBLANK(D12),ISBLANK(E12)),IF(OR(B12="ALI",B12="AIE"),"L",IF(OR(B12="EE",B12="SE",B12="CE"),"A","")),IF(B12="EE",IF(E12>=3,IF(D12>=5,"H","A"),IF(E12>=2,IF(D12>=16,"H",IF(D12<=4,"L","A")),IF(D12<=15,"L","A"))),IF(OR(B12="SE",B12="CE"),IF(E12>=4,IF(D12>=6,"H","A"),IF(E12>=2,IF(D12>=20,"H",IF(D12<=5,"L","A")),IF(D12<=19,"L","A"))),IF(OR(B12="ALI",B12="AIE"),IF(E12>=6,IF(D12>=20,"H","A"),IF(E12>=2,IF(D12>=51,"H",IF(D12<=19,"L","A")),IF(D12<=50,"L","A"))),"")))) | J12: =CONCATENATE(B12,C12) | K12: =IF(OR(H12="",H12=0),L12,H12) | L12: =IF(NOT(ISERROR(VLOOKUP(B12,Deflatores!G$42:H$64,2,FALSE))),VLOOKUP(B12,Deflatores!G$42:H$64,2,FALSE),IF(OR(ISBLANK(C12),ISBLANK(B12)),"",VLOOKUP(C12,Deflatores!G$4:H$38,2,FALSE)*H12+VLOOKUP(C12,Deflatores!G$4:I$38,3,FALSE)))
F13: =IF(ISBLANK(B13),"",IF(I13="L","Baixa",IF(I13="A","Média",IF(I13="","","Alta")))) | G13: =CONCATENATE(B13,I13) | H13: =IF(ISBLANK(B13),"",IF(B13="ALI",IF(I13="L",7,IF(I13="A",10,15)),IF(B13="AIE",IF(I13="L",5,IF(I13="A",7,10)),IF(B13="SE",IF(I13="L",4,IF(I13="A",5,7)),IF(OR(B13="EE",B13="CE"),IF(I13="L",3,IF(I13="A",4,6)),0))))) | I13: =IF(OR(ISBLANK(D13),ISBLANK(E13)),IF(OR(B13="ALI",B13="AIE"),"L",IF(OR(B13="EE",B13="SE",B13="CE"),"A","")),IF(B13="EE",IF(E13>=3,IF(D13>=5,"H","A"),IF(E13>=2,IF(D13>=16,"H",IF(D13<=4,"L","A")),IF(D13<=15,"L","A"))),IF(OR(B13="SE",B13="CE"),IF(E13>=4,IF(D13>=6,"H","A"),IF(E13>=2,IF(D13>=20,"H",IF(D13<=5,"L","A")),IF(D13<=19,"L","A"))),IF(OR(B13="ALI",B13="AIE"),IF(E13>=6,IF(D13>=20,"H","A"),IF(E13>=2,IF(D13>=51,"H",IF(D13<=19,"L","A")),IF(D13<=50,"L","A"))),"")))) | J13: =CONCATENATE(B13,C13) | K13: =IF(OR(H13="",H13=0),L13,H13) | L13: =IF(NOT(ISERROR(VLOOKUP(B13,Deflatores!G$42:H$64,2,FALSE))),VLOOKUP(B13,Deflatores!G$42:H$64,2,FALSE),IF(OR(ISBLANK(C13),ISBLANK(B13)),"",VLOOKUP(C13,Deflatores!G$4:H$38,2,FALSE)*H13+VLOOKUP(C13,Deflatores!G$4:I$38,3,FALSE)))
F14: =IF(ISBLANK(B14),"",IF(I14="L","Baixa",IF(I14="A","Média",IF(I14="","","Alta")))) | G14: =CONCATENATE(B14,I14) | H14: =IF(ISBLANK(B14),"",IF(B14="ALI",IF(I14="L",7,IF(I14="A",10,15)),IF(B14="AIE",IF(I14="L",5,IF(I14="A",7,10)),IF(B14="SE",IF(I14="L",4,IF(I14="A",5,7)),IF(OR(B14="EE",B14="CE"),IF(I14="L",3,IF(I14="A",4,6)),0))))) | I14: =IF(OR(ISBLANK(D14),ISBLANK(E14)),IF(OR(B14="ALI",B14="AIE"),"L",IF(OR(B14="EE",B14="SE",B14="CE"),"A","")),IF(B14="EE",IF(E14>=3,IF(D14>=5,"H","A"),IF(E14>=2,IF(D14>=16,"H",IF(D14<=4,"L","A")),IF(D14<=15,"L","A"))),IF(OR(B14="SE",B14="CE"),IF(E14>=4,IF(D14>=6,"H","A"),IF(E14>=2,IF(D14>=20,"H",IF(D14<=5,"L","A")),IF(D14<=19,"L","A"))),IF(OR(B14="ALI",B14="AIE"),IF(E14>=6,IF(D14>=20,"H","A"),IF(E14>=2,IF(D14>=51,"H",IF(D14<=19,"L","A")),IF(D14<=50,"L","A"))),"")))) | J14: =CONCATENATE(B14,C14) | K14: =IF(OR(H14="",H14=0),L14,H14) | L14: =IF(NOT(ISERROR(VLOOKUP(B14,Deflatores!G$42:H$64,2,FALSE))),VLOOKUP(B14,Deflatores!G$42:H$64,2,FALSE),IF(OR(ISBLANK(C14),ISBLANK(B14)),"",VLOOKUP(C14,Deflatores!G$4:H$38,2,FALSE)*H14+VLOOKUP(C14,Deflatores!G$4:I$38,3,FALSE)))
F15: =IF(ISBLANK(B15),"",IF(I15="L","Baixa",IF(I15="A","Média",IF(I15="","","Alta")))) | G15: =CONCATENATE(B15,I15) | H15: =IF(ISBLANK(B15),"",IF(B15="ALI",IF(I15="L",7,IF(I15="A",10,15)),IF(B15="AIE",IF(I15="L",5,IF(I15="A",7,10)),IF(B15="SE",IF(I15="L",4,IF(I15="A",5,7)),IF(OR(B15="EE",B15="CE"),IF(I15="L",3,IF(I15="A",4,6)),0))))) | I15: =IF(OR(ISBLANK(D15),ISBLANK(E15)),IF(OR(B15="ALI",B15="AIE"),"L",IF(OR(B15="EE",B15="SE",B15="CE"),"A","")),IF(B15="EE",IF(E15>=3,IF(D15>=5,"H","A"),IF(E15>=2,IF(D15>=16,"H",IF(D15<=4,"L","A")),IF(D15<=15,"L","A"))),IF(OR(B15="SE",B15="CE"),IF(E15>=4,IF(D15>=6,"H","A"),IF(E15>=2,IF(D15>=20,"H",IF(D15<=5,"L","A")),IF(D15<=19,"L","A"))),IF(OR(B15="ALI",B15="AIE"),IF(E15>=6,IF(D15>=20,"H","A"),IF(E15>=2,IF(D15>=51,"H",IF(D15<=19,"L","A")),IF(D15<=50,"L","A"))),"")))) | J15: =CONCATENATE(B15,C15) | K15: =IF(OR(H15="",H15=0),L15,H15) | L15: =IF(NOT(ISERROR(VLOOKUP(B15,Deflatores!G$42:H$64,2,FALSE))),VLOOKUP(B15,Deflatores!G$42:H$64,2,FALSE),IF(OR(ISBLANK(C15),ISBLANK(B15)),"",VLOOKUP(C15,Deflatores!G$4:H$38,2,FALSE)*H15+VLOOKUP(C15,Deflatores!G$4:I$38,3,FALSE)))
F16: =IF(ISBLANK(B16),"",IF(I16="L","Baixa",IF(I16="A","Média",IF(I16="","","Alta")))) | G16: =CONCATENATE(B16,I16) | H16: =IF(ISBLANK(B16),"",IF(B16="ALI",IF(I16="L",7,IF(I16="A",10,15)),IF(B16="AIE",IF(I16="L",5,IF(I16="A",7,10)),IF(B16="SE",IF(I16="L",4,IF(I16="A",5,7)),IF(OR(B16="EE",B16="CE"),IF(I16="L",3,IF(I16="A",4,6)),0))))) | I16: =IF(OR(ISBLANK(D16),ISBLANK(E16)),IF(OR(B16="ALI",B16="AIE"),"L",IF(OR(B16="EE",B16="SE",B16="CE"),"A","")),IF(B16="EE",IF(E16>=3,IF(D16>=5,"H","A"),IF(E16>=2,IF(D16>=16,"H",IF(D16<=4,"L","A")),IF(D16<=15,"L","A"))),IF(OR(B16="SE",B16="CE"),IF(E16>=4,IF(D16>=6,"H","A"),IF(E16>=2,IF(D16>=20,"H",IF(D16<=5,"L","A")),IF(D16<=19,"L","A"))),IF(OR(B16="ALI",B16="AIE"),IF(E16>=6,IF(D16>=20,"H","A"),IF(E16>=2,IF(D16>=51,"H",IF(D16<=19,"L","A")),IF(D16<=50,"L","A"))),"")))) | J16: =CONCATENATE(B16,C16) | K16: =IF(OR(H16="",H16=0),L16,H16) | L16: =IF(NOT(ISERROR(VLOOKUP(B16,Deflatores!G$42:H$64,2,FALSE))),VLOOKUP(B16,Deflatores!G$42:H$64,2,FALSE),IF(OR(ISBLANK(C16),ISBLANK(B16)),"",VLOOKUP(C16,Deflatores!G$4:H$38,2,FALSE)*H16+VLOOKUP(C16,Deflatores!G$4:I$38,3,FALSE)))
F17: =IF(ISBLANK(B17),"",IF(I17="L","Baixa",IF(I17="A","Média",IF(I17="","","Alta")))) | G17: =CONCATENATE(B17,I17) | H17: =IF(ISBLANK(B17),"",IF(B17="ALI",IF(I17="L",7,IF(I17="A",10,15)),IF(B17="AIE",IF(I17="L",5,IF(I17="A",7,10)),IF(B17="SE",IF(I17="L",4,IF(I17="A",5,7)),IF(OR(B17="EE",B17="CE"),IF(I17="L",3,IF(I17="A",4,6)),0))))) | I17: =IF(OR(ISBLANK(D17),ISBLANK(E17)),IF(OR(B17="ALI",B17="AIE"),"L",IF(OR(B17="EE",B17="SE",B17="CE"),"A","")),IF(B17="EE",IF(E17>=3,IF(D17>=5,"H","A"),IF(E17>=2,IF(D17>=16,"H",IF(D17<=4,"L","A")),IF(D17<=15,"L","A"))),IF(OR(B17="SE",B17="CE"),IF(E17>=4,IF(D17>=6,"H","A"),IF(E17>=2,IF(D17>=20,"H",IF(D17<=5,"L","A")),IF(D17<=19,"L","A"))),IF(OR(B17="ALI",B17="AIE"),IF(E17>=6,IF(D17>=20,"H","A"),IF(E17>=2,IF(D17>=51,"H",IF(D17<=19,"L","A")),IF(D17<=50,"L","A"))),"")))) | J17: =CONCATENATE(B17,C17) | K17: =IF(OR(H17="",H17=0),L17,H17) | L17: =IF(NOT(ISERROR(VLOOKUP(B17,Deflatores!G$42:H$64,2,FALSE))),VLOOKUP(B17,Deflatores!G$42:H$64,2,FALSE),IF(OR(ISBLANK(C17),ISBLANK(B17)),"",VLOOKUP(C17,Deflatores!G$4:H$38,2,FALSE)*H17+VLOOKUP(C17,Deflatores!G$4:I$38,3,FALSE)))
F18: =IF(ISBLANK(B18),"",IF(I18="L","Baixa",IF(I18="A","Média",IF(I18="","","Alta")))) | G18: =CONCATENATE(B18,I18) | H18: =IF(ISBLANK(B18),"",IF(B18="ALI",IF(I18="L",7,IF(I18="A",10,15)),IF(B18="AIE",IF(I18="L",5,IF(I18="A",7,10)),IF(B18="SE",IF(I18="L",4,IF(I18="A",5,7)),IF(OR(B18="EE",B18="CE"),IF(I18="L",3,IF(I18="A",4,6)),0))))) | I18: =IF(OR(ISBLANK(D18),ISBLANK(E18)),IF(OR(B18="ALI",B18="AIE"),"L",IF(OR(B18="EE",B18="SE",B18="CE"),"A","")),IF(B18="EE",IF(E18>=3,IF(D18>=5,"H","A"),IF(E18>=2,IF(D18>=16,"H",IF(D18<=4,"L","A")),IF(D18<=15,"L","A"))),IF(OR(B18="SE",B18="CE"),IF(E18>=4,IF(D18>=6,"H","A"),IF(E18>=2,IF(D18>=20,"H",IF(D18<=5,"L","A")),IF(D18<=19,"L","A"))),IF(OR(B18="ALI",B18="AIE"),IF(E18>=6,IF(D18>=20,"H","A"),IF(E18>=2,IF(D18>=51,"H",IF(D18<=19,"L","A")),IF(D18<=50,"L","A"))),"")))) | J18: =CONCATENATE(B18,C18) | K18: =IF(OR(H18="",H18=0),L18,H18) | L18: =IF(NOT(ISERROR(VLOOKUP(B18,Deflatores!G$42:H$64,2,FALSE))),VLOOKUP(B18,Deflatores!G$42:H$64,2,FALSE),IF(OR(ISBLANK(C18),ISBLANK(B18)),"",VLOOKUP(C18,Deflatores!G$4:H$38,2,FALSE)*H18+VLOOKUP(C18,Deflatores!G$4:I$38,3,FALSE)))
F19: =IF(ISBLANK(B19),"",IF(I19="L","Baixa",IF(I19="A","Média",IF(I19="","","Alta")))) | G19: =CONCATENATE(B19,I19) | H19: =IF(ISBLANK(B19),"",IF(B19="ALI",IF(I19="L",7,IF(I19="A",10,15)),IF(B19="AIE",IF(I19="L",5,IF(I19="A",7,10)),IF(B19="SE",IF(I19="L",4,IF(I19="A",5,7)),IF(OR(B19="EE",B19="CE"),IF(I19="L",3,IF(I19="A",4,6)),0))))) | I19: =IF(OR(ISBLANK(D19),ISBLANK(E19)),IF(OR(B19="ALI",B19="AIE"),"L",IF(OR(B19="EE",B19="SE",B19="CE"),"A","")),IF(B19="EE",IF(E19>=3,IF(D19>=5,"H","A"),IF(E19>=2,IF(D19>=16,"H",IF(D19<=4,"L","A")),IF(D19<=15,"L","A"))),IF(OR(B19="SE",B19="CE"),IF(E19>=4,IF(D19>=6,"H","A"),IF(E19>=2,IF(D19>=20,"H",IF(D19<=5,"L","A")),IF(D19<=19,"L","A"))),IF(OR(B19="ALI",B19="AIE"),IF(E19>=6,IF(D19>=20,"H","A"),IF(E19>=2,IF(D19>=51,"H",IF(D19<=19,"L","A")),IF(D19<=50,"L","A"))),"")))) | J19: =CONCATENATE(B19,C19) | K19: =IF(OR(H19="",H19=0),L19,H19) | L19: =IF(NOT(ISERROR(VLOOKUP(B19,Deflatores!G$42:H$64,2,FALSE))),VLOOKUP(B19,Deflatores!G$42:H$64,2,FALSE),IF(OR(ISBLANK(C19),ISBLANK(B19)),"",VLOOKUP(C19,Deflatores!G$4:H$38,2,FALSE)*H19+VLOOKUP(C19,Deflatores!G$4:I$38,3,FALSE)))
... F522: =IF(ISBLANK(B522),"",IF(I522="L","Baixa",IF(I522="A","Média",IF(I522="","","Alta")))) | G522: =CONCATENATE(B522,I522) | H522: =IF(ISBLANK(B522),"",IF(B522="ALI",IF(I522="L",7,IF(I522="A",10,15)),IF(B522="AIE",IF(I522="L",5,IF(I522="A",7,10)),IF(B522="SE",IF(I522="L",4,IF(I522="A",5,7)),IF(OR(B522="EE",B522="CE"),IF(I522="L",3,IF(I522="A",4,6)),0))))) | I522: =IF(OR(ISBLANK(D522),ISBLANK(E522)),IF(OR(B522="ALI",B522="AIE"),"L",IF(OR(B522="EE",B522="SE",B522="CE"),"A","")),IF(B522="EE",IF(E522>=3,IF(D522>=5,"H","A"),IF(E522>=2,IF(D522>=16,"H",IF(D522<=4,"L","A")),IF(D522<=15,"L","A"))),IF(OR(B522="SE",B522="CE"),IF(E522>=4,IF(D522>=6,"H","A"),IF(E522>=2,IF(D522>=20,"H",IF(D522<=5,"L","A")),IF(D522<=19,"L","A"))),IF(OR(B522="ALI",B522="AIE"),IF(E522>=6,IF(D522>=20,"H","A"),IF(E522>=2,IF(D522>=51,"H",IF(D522<=19,"L","A")),IF(D522<=50,"L","A"))),"")))) | J522: =CONCATENATE(B522,C522) | K522: =IF(OR(H522="",H522=0),L522,H522) | L522: =IF(NOT(ISERROR(VLOOKUP(B522,Deflatores!G$42:H$64,2,FALSE))),VLOOKUP(B522,Deflatores!G$42:H$64,2,FALSE),IF(OR(ISBLANK(C522),ISBLANK(B522)),"",VLOOKUP(C522,Deflatores!G$4:H$38,2,FALSE)*H522+VLOOKUP(C522,Deflatores!G$4:I$38,3,FALSE)))

Sheet Deflatores
A1: Itens Não Mensuráveis
A2: Tipo de Manutenção na Função | G2: Sigla | H2: Contribuição em PF Local | J2: PF IFPUG | K2: PF Local FS
A3: Contrato | B3: Descrição | F3: Origem | H3: Percentual (%) | I3: Fixa (PF)
A4: Adicionada | B4: Inclusão | G4: I | H4: 1 | J4: =SUMIF(Funções!$C$8:$C$522,Deflatores!G4,Funções!$H$8:$H$522) | K4: =IF(H4="",COUNTIF(Funções!C$8:C$522,G4)*I4,H4*J4)
A5: Alterada | B5: Alteração (sem conhecimento do Fator de Impacto) | F5: SISP – 4.2 Projeto de Melhoria | G5: A | H5: 0.5 | J5: =SUMIF(Funções!$C$8:$C$522,Deflatores!G5,Funções!$H$8:$H$522) | K5: =IF(H5="",COUNTIF(Funções!C$8:C$522,G5)*I5,H5*J5)
A6: Excluída | B6: Exclusão | F6: SISP – 4.2 Projeto de Melhoria | G6: E | H6: 0.3 | J6: =SUMIF(Funções!$C$8:$C$522,Deflatores!G6,Funções!$H$8:$H$522) | K6: =IF(H6="",COUNTIF(Funções!C$8:C$522,G6)*I6,H6*J6)
B7: Alteração (50%) de função desenvolvida ou já alterada pela empresa atual | F7: SISP – 4.2 Projeto de Melhoria | G7: A50 | H7: 0.5 | J7: =SUMIF(Funções!$C$8:$C$522,Deflatores!G7,Funções!$H$8:$H$522) | K7: =IF(H7="",COUNTIF(Funções!C$8:C$522,G7)*I7,H7*J7)
B8: Alteração (75%) de função não desenv. e ainda não alterada pela empresa atual | F8: SISP – 4.2 Projeto de Melhoria | G8: A75 | H8: 0.75 | J8: =SUMIF(Funções!$C$8:$C$522,Deflatores!G8,Funções!$H$8:$H$522) | K8: =IF(H8="",COUNTIF(Funções!C$8:C$522,G8)*I8,H8*J8)
B9: Alteração (75%+15%): o mesmo acima + redocumentar a função | F9: SISP – 4.2 Projeto de Melhoria | G9: A90 | H9: 0.9 | J9: =SUMIF(Funções!$C$8:$C$522,Deflatores!G9,Funções!$H$8:$H$522) | K9: =IF(H9="",COUNTIF(Funções!C$8:C$522,G9)*I9,H9*J9)
B10: Migração de Dados | F10: SISP – 4.3 Projetos de Migração de Dados | G10: PMD | H10: 1 | J10: =SUMIF(Funções!$C$8:$C$522,Deflatores!G10,Funções!$H$8:$H$522) | K10: =IF(H10="",COUNTIF(Funções!C$8:C$522,G10)*I10,H10*J10)
B11: Corretiva (sem conhecimento do Fator de Impacto) | F11: SISP – 4.4 Manutenção Corretiva | G11: COR | H11: 0.5 | J11: =SUMIF(Funções!$C$8:$C$522,Deflatores!G11,Funções!$H$8:$H$522) | K11: =IF(H11="",COUNTIF(Funções!C$8:C$522,G11)*I11,H11*J11)
B12: Corretiva (50%) - Fora da garantia (mesma empresa) | F12: SISP – 4.4 Manutenção Corretiva | G12: COR50 | H12: 0.5 | J12: =SUMIF(Funções!$C$8:$C$522,Deflatores!G12,Funções!$H$8:$H$522) | K12: =IF(H12="",COUNTIF(Funções!C$8:C$522,G12)*I12,H12*J12)
B13: Corretiva (75%) - Fora da garantia (outra empresa) | F13: SISP – 4.4 Manutenção Corretiva | G13: COR75 | H13: 0.75 | J13: =SUMIF(Funções!$C$8:$C$522,Deflatores!G13,Funções!$H$8:$H$522) | K13: =IF(H13="",COUNTIF(Funções!C$8:C$522,G13)*I13,H13*J13)
B14: Corretiva (75%+15%) - Fora da garantia (outra empresa) + Redocumentação | F14: SISP – 4.4 Manutenção Corretiva | G14: COR90 | H14: 0.9 | J14: =SUMIF(Funções!$C$8:$C$522,Deflatores!G14,Funções!$H$8:$H$522) | K14: =IF(H14="",COUNTIF(Funções!C$8:C$522,G14)*I14,H14*J14)
B15: Corretiva em Garantia | F15: SISP – 4.4 Manutenção Corretiva | G15: GAR | H15: 0 | J15: =SUMIF(Funções!$C$8:$C$522,Deflatores!G15,Funções!$H$8:$H$522) | K15: =IF(H15="",COUNTIF(Funções!C$8:C$522,G15)*I15,H15*J15)
B16: Mudança de Plataforma - Linguagem de Programação | F16: SISP – 4.5.1 Mudança de Plataforma – Linguagem de Programação | G16: MLP | H16: 1 | J16: =SUMIF(Funções!$C$8:$C$522,Deflatores!G16,Funções!$H$8:$H$522) | K16: =IF(H16="",COUNTIF(Funções!C$8:C$522,G16)*I16,H16*J16)
B17: Mudança de Plataforma - Banco de Dados (outro paradigma) | F17: SISP – 4.5.2 Mudança de Plataforma – Banco de Dados | G17: MBO | H17: 1 | J17: =SUMIF(Funções!$C$8:$C$522,Deflatores!G17,Funções!$H$8:$H$522) | K17: =IF(H17="",COUNTIF(Funções!C$8:C$522,G17)*I17,H17*J17)
B18: Mudança de Plataforma - Banco de Dados (mesmo paradigma com alterações) | F18: SISP – 4.5.2 Mudança de Plataforma – Banco de Dados | G18: MBM | H18: 0.3 | J18: =SUMIF(Funções!$C$8:$C$522,Deflatores!G18,Funções!$H$8:$H$522) | K18: =IF(H18="",COUNTIF(Funções!C$8:C$522,G18)*I18,H18*J18)
... B21: Atualização de Versão – Banco de Dados | F21: SISP – 4.6.3 Atualização de Versão – Banco de Dados | G21: ABD | H21: 0.3 | J21: =SUMIF(Funções!$C$8:$C$522,Deflatores!G21,Funções!$H$8:$H$522) | K21: =IF(H21="",COUNTIF(Funções!C$8:C$522,G21)*I21,H21*J21)
B22: Manutenção Cosmética | F22: SISP – 4.7 Manutenção Cosmética | G22: COS | I22: 0.6 | J22: =SUMIF(Funções!$C$8:$C$522,Deflatores!G22,Funções!$H$8:$H$522) | K22: =IF(H22="",COUNTIF(Funções!C$8:C$522,G22)*I22,H22*J22)
B23: Adaptação em Funcionalidades sem Alteração de Requisitos Funcionais (sem conhecimento do Fator de Impacto) | F23: SISP – 4.8 Adaptação em Funcionalidades sem Alteração de Requisitos Funcionais | G23: ARN | H23: 0.5 | J23: =SUMIF(Funções!$C$8:$C$522,Deflatores!G23,Funções!$H$8:$H$522) | K23: =IF(H23="",COUNTIF(Funções!C$8:C$522,G23)*I23,H23*J23)
B24: Adaptação em Funcionalidades sem Alteração de Requisitos Funcionais (50%) (em função desenvolvida ou já alterada pela empresa atual) | F24: SISP – 4.8 Adaptação em Funcionalidades sem Alteração de Requisitos Funcionais | G24: ARN50 | H24: 0.5 | J24: =SUMIF(Funções!$C$8:$C$522,Deflatores!G24,Funções!$H$8:$H$522) | K24: =IF(H24="",COUNTIF(Funções!C$8:C$522,G24)*I24,H24*J24)
B25: Adaptação em Funcionalidades sem Alteração de Requisitos Funcionais (75%) (em função não desenvolvida e ainda não alterada pela empresa atual) | F25: SISP – 4.8 Adaptação em Funcionalidades sem Alteração de Requisitos Funcionais | G25: ARN75 | H25: 0.75 | J25: =SUMIF(Funções!$C$8:$C$522,Deflatores!G25,Funções!$H$8:$H$522) | K25: =IF(H25="",COUNTIF(Funções!C$8:C$522,G25)*I25,H25*J25)
B26: Atualização de Dados sem Consulta Prévia | F26: SISP – 4.9.1 Apuração Especial – Base de Dados | G26: ADS | H26: 1 | J26: =SUMIF(Funções!$C$8:$C$522,Deflatores!G26,Funções!$H$8:$H$522) | K26: =IF(H26="",COUNTIF(Funções!C$8:C$522,G26)*I26,H26*J26)
B27: Consulta Prévia sem Atualização | F27: SISP – 4.9.1 Apuração Especial – Base de Dados | G27: CPA | H27: 1 | J27: =SUMIF(Funções!$C$8:$C$522,Deflatores!G27,Funções!$H$8:$H$522) | K27: =IF(H27="",COUNTIF(Funções!C$8:C$522,G27)*I27,H27*J27)
B28: Atualização de Dados com Consulta Prévia | F28: SISP – 4.9.1 Apuração Especial – Base de Dados | G28: ADC | H28: 0.6 | J28: =SUMIF(Funções!$C$8:$C$522,Deflatores!G28,Funções!$H$8:$H$522) | K28: =IF(H28="",COUNTIF(Funções!C$8:C$522,G28)*I28,H28*J28)
B29: Apuração Especial – Geração de Relatórios | F29: SISP – 4.9.2 Apuração Especial – Geração de Relatórios | G29: AGR | H29: 1 | J29: =SUMIF(Funções!$C$8:$C$522,Deflatores!G29,Funções!$H$8:$H$522) | K29: =IF(H29="",COUNTIF(Funções!C$8:C$522,G29)*I29,H29*J29)
B30: Apuração Especial – Reexecução | F30: SISP – 4.9.3 Apuração Especial – Reexecução | G30: AER | H30: 0.1 | J30: =SUMIF(Funções!$C$8:$C$522,Deflatores!G30,Funções!$H$8:$H$522) | K30: =IF(H30="",COUNTIF(Funções!C$8:C$522,G30)*I30,H30*J30)
B31: Atualização de Dados | F31: SISP – 4.10 Atualização de Dados | G31: ATD | H31: 0.1 | J31: =SUMIF(Funções!$C$8:$C$522,Deflatores!G31,Funções!$H$8:$H$522) | K31: =IF(H31="",COUNTIF(Funções!C$8:C$522,G31)*I31,H31*J31)
B32: Manutenção de Documentação de Sistemas Legados | F32: SISP – 4.12 Manutenção de Documentação de Sistemas Legados | G32: MSL | H32: 0.25 | J32: =SUMIF(Funções!$C$8:$C$522,Deflatores!G32,Funções!$H$8:$H$522) | K32: =IF(H32="",COUNTIF(Funções!C$8:C$522,G32)*I32,H32*J32)
B33: Verificação de Erros (Sem Documentação de Teste existente) | F33: SISP – 4.13 Verificação de Erros | G33: VES | H33: 0.2 | J33: =SUMIF(Funções!$C$8:$C$522,Deflatores!G33,Funções!$H$8:$H$522) | K33: =IF(H33="",COUNTIF(Funções!C$8:C$522,G33)*I33,H33*J33)
B34: Verificação de Erros (Com Documentação de Teste existente) | F34: SISP – 4.13 Verificação de Erros | G34: VEC | H34: 0.15 | J34: =SUMIF(Funções!$C$8:$C$522,Deflatores!G34,Funções!$H$8:$H$522) | K34: =IF(H34="",COUNTIF(Funções!C$8:C$522,G34)*I34,H34*J34)
... B36: Componente Interno Reusável | F36: SISP – 4.15 Componente Interno Reusável | G36: CIR | H36: 1 | J36: =SUMIF(Funções!$C$8:$C$522,Deflatores!G36,Funções!$H$8:$H$522) | K36: =IF(H36="",COUNTIF(Funções!C$8:C$522,G36)*I36,H36*J36)
G37: . | J37: =SUMIF(Funções!$C$8:$C$522,Deflatores!G37,Funções!$H$8:$H$522) | K37: =IF(H37="",COUNTIF(Funções!C$8:C$522,G37)*I37,H37*J37) | L37: ALI
G38: . | J38: =SUMIF(Funções!$C$8:$C$522,Deflatores!G38,Funções!$H$8:$H$522) | K38: =IF(H38="",COUNTIF(Funções!C$8:C$522,G38)*I38,H38*J38) | L38: AIE
L39: EE
A40: Itens Não Mensuráveis | G40: Sigla | H40: Contribuição em PF Local | J40: Quantidade | K40: PF Local FS | L40: CE
A41: Contrato | B41: Descrição | F41: Origem | L41: SE
B42: Páginas Estáticas | F42: SISP – 4.11 Desenvolvimento, Manutenção e Publicação de Paginas Estáticas de Intranet, Internet ou Portal | G42: PAG | H42: 0.6 | J42: =COUNTIF(Funções!B$8:B$522,G42) | K42: =SUMIF(Funções!B$8:B$522,$G42,Funções!K$8:K$522) | L42: =""&G42
B43: Manutenção Cosmética (atrelada a algo não funcional) | F43: SISP – 4.7 Manutenção Cosmética | G43: COSNF | H43: 0.6 | J43: =COUNTIF(Funções!B$8:B$522,G43) | K43: =SUMIF(Funções!B$8:B$522,$G43,Funções!K$8:K$522) | L43: =""&G43
...

Sheet Sumário 1
A1: Sumário da Contagem
A4: =Contagem!A5&" : "&Contagem!F5 | F4: =Contagem!A8&" : "&Contagem!F8
A5: =Contagem!A9&" : "&Contagem!F9 | F5: =Contagem!A10&" : "&Contagem!F10
A6: =Contagem!A4&" : "&Contagem!F4 | F6: ="Tipo de Contagem : "&Contagem!F6
A7: Tipo de Função | C7: Complexidade Funcional | G7: Total PF IFPUG por Complexidade | H7: % | J7: Total PF Local FS por tipo de manutenção básica | L7: %
B10: EE | C10: =COUNTIF(Funções!G8:G522,"EEL") | E10: Baixa | F10: x 3 | G10: =C10*3 | J10: =Deflatores!$G$4&"=" | K10: =SUMIF(Funções!$J$8:$J$522,"EE"&Deflatores!G4,Funções!$L$8:$L$522)
C11: =COUNTIF(Funções!G8:G522,"EEA") | E11: Média | F11: x 4 | G11: =C11*4 | J11: =Deflatores!$G$5&"=" | K11: =SUMIF(Funções!$J$8:$J$522,"EE"&Deflatores!G5,Funções!$L$8:$L$522)
C12: =COUNTIF(Funções!G8:G522,"EEH") | E12: Alta | F12: x 6 | G12: =C12*6 | J12: =Deflatores!$G$6&"=" | K12: =SUMIF(Funções!$J$8:$J$522,"EE"&Deflatores!G6,Funções!$L$8:$L$522)
B14: Qtd Total | C14: =SUM(C10:C12) | F14: Total | G14: =SUM(G10:G12) | H14: =IF($G$45<>0,G14/$G$45,"") | K14: =SUM(K10:K13) | L14: =IF('Sumário 2'!L11<>0,K14/'Sumário 2'!L11,"")
B17: SE | C17: =COUNTIF(Funções!G8:G522,"SEL") | E17: Baixa | F17: x 4 | G17: =C17*4 | J17: =Deflatores!$G$4&"=" | K17: =SUMIF(Funções!$J$8:$J$522,"SE"&Deflatores!$G$4,Funções!$L$8:$L$522)
C18: =COUNTIF(Funções!G8:G522,"SEA") | E18: Média | F18: x 5 | G18: =C18*5 | J18: =Deflatores!$G$5&"=" | K18: =SUMIF(Funções!$J$8:$J$522,"SE"&Deflatores!$G$5,Funções!$L$8:$L$522)
C19: =COUNTIF(Funções!G8:G522,"SEH") | E19: Alta | F19: x 7 | G19: =C19*7 | J19: =Deflatores!$G$6&"=" | K19: =SUMIF(Funções!$J$8:$J$522,"SE"&Deflatores!$G$6,Funções!$L$8:$L$522)
B21: Qtd Total | C21: =SUM(C17:C19) | F21: Total | G21: =SUM(G17:G19) | H21: =IF($G$45<>0,G21/$G$45,"") | K21: =SUM(K17:K20) | L21: =IF('Sumário 2'!L11<>0,K21/'Sumário 2'!L11,"")
B24: CE | C24: =COUNTIF(Funções!G8:G522,"CEL") | E24: Baixa | F24: x 3 | G24: =C24*3 | J24: =Deflatores!$G$4&"=" | K24: =SUMIF(Funções!$J$8:$J$522,"CE"&Deflatores!$G$4,Funções!$L$8:$L$522)
C25: =COUNTIF(Funções!G8:G522,"CEA") | E25: Média | F25: x 4 | G25: =C25*4 | J25: =Deflatores!$G$5&"=" | K25: =SUMIF(Funções!$J$8:$J$522,"CE"&Deflatores!$G$5,Funções!$L$8:$L$522)
C26: =COUNTIF(Funções!G8:G522,"CEH") | E26: Alta | F26: x 6 | G26: =C26*6 | J26: =Deflatores!$G$6&"=" | K26: =SUMIF(Funções!$J$8:$J$522,"CE"&Deflatores!$G$6,Funções!$L$8:$L$522)
B28: Qtd Total | C28: =SUM(C24:C26) | F28: Total | G28: =SUM(G24:G26) | H28: =IF($G$45<>0,G28/$G$45,"") | K28: =SUM(K24:K27) | L28: =IF('Sumário 2'!L11<>0,K28/'Sumário 2'!L11,"")
B31: ALI | C31: =COUNTIF(Funções!G8:G522,"ALIL") | E31: Baixa | F31: x 7 | G31: =C31*7 | J31: =Deflatores!$G$4&"=" | K31: =SUMIF(Funções!$J$8:$J$522,"ALI"&Deflatores!$G$4,Funções!$L$8:$L$522)
C32: =COUNTIF(Funções!G8:G522,"ALIA") | E32: Média | F32: x 10 | G32: =C32*10 | J32: =Deflatores!$G$5&"=" | K32: =SUMIF(Funções!$J$8:$J$522,"ALI"&Deflatores!$G$5,Funções!$L$8:$L$522)
C33: =COUNTIF(Funções!G8:G522,"ALIH") | E33: Alta | F33: x 15 | G33: =C33*15 | J33: =Deflatores!$G$6&"=" | K33: =SUMIF(Funções!$J$8:$J$522,"ALI"&Deflatores!$G$6,Funções!$L$8:$L$522)
B35: Qtd Total | C35: =SUM(C31:C33) | F35: Total | G35: =SUM(G31:G33) | H35: =IF($G$45<>0,G35/$G$45,"") | K35: =SUM(K31:K34) | L35: =IF('Sumário 2'!L11<>0,K35/'Sumário 2'!L11,"")
B38: AIE | C38: =COUNTIF(Funções!G8:G522,"AIEL") | E38: Baixa | F38: x 5 | G38: =C38*5 | J38: =Deflatores!$G$4&"=" | K38: =SUMIF(Funções!$J$8:$J$522,"AIE"&Deflatores!$G$4,Funções!$L$8:$L$522)
C39: =COUNTIF(Funções!G8:G522,"AIEA") | E39: Média | F39: x 7 | G39: =C39*7 | J39: =Deflatores!$G$5&"=" | K39: =SUMIF(Funções!$J$8:$J$522,"AIE"&Deflatores!$G$5,Funções!$L$8:$L$522)
C40: =COUNTIF(Funções!G8:G522,"AIEH") | E40: Alta | F40: x 10 | G40: =C40*10 | J40: =Deflatores!$G$6&"=" | K40: =SUMIF(Funções!$J$8:$J$522,"AIE"&Deflatores!$G$6,Funções!$L$8:$L$522)
B42: Qtd Total | C42: =SUM(C38:C40) | F42: Total | G42: =SUM(G38:G40) | H42: =IF($G$45<>0,G42/$G$45,"") | K42: =SUM(K38:K41) | L42: =IF('Sumário 2'!L11<>0,K42/'Sumário 2'!L11,"")
B45: Total PF não ajustados (contagem detalhada) | G45: =SUM(G14+G21+G28+G35+G42)
B46: Total PF não ajustados (contagem estimativa) | G46: =(C10+C11+C12)*4+(C17+C18+C19)*5+(C24+C25+C26)*4+(C31+C32+C33)*7+(C38+C39+C40)*5
B47: Total PF não ajustados (contagem indicativa) | G47: =(C31+C32+C33)*35+(C38+C39+C40)*15

Sheet Sumário 2
A1: Sumário por Deflatores e Itens não mensuráveis
A4: =Contagem!A5&" : "&Contagem!F5 | F4: =Contagem!A8&" : "&Contagem!F8
A5: =Contagem!A9&" : "&Contagem!F9 | F5: =Contagem!A10&" : "&Contagem!F10
A6: =Contagem!A4&" : "&Contagem!F4 | F6: ="Tipo de Contagem : "&Contagem!F6
B9: Deflatores aplicados a Itens Funcionais | E9: Quantidade | F9: PF IFPUG | G9: Deflator | H9: Contrib. Fixa | I9: PF Local da FS | J9: % LOCAL
B10: =""&Deflatores!B4 | D10: =""&Deflatores!G4 | E10: =IF(D10="","",COUNTIF(Funções!C$8:C$522,D10)) | F10: =SUMIF(Funções!$C$8:$C$522,Deflatores!G4,Funções!$H$8:$H$522) | G10: =IF(ISBLANK(Deflatores!H4),"",Deflatores!H4) | H10: =IF(ISBLANK(Deflatores!I4),"",Deflatores!I4) | I10: =IF(F10=0,Deflatores!K4,F10*G10) | J10: =IF($L$11<>0,I10/$L$11,"") | L10: PF Local da FS
B11: =""&Deflatores!B5 | D11: =""&Deflatores!G5 | E11: =IF(D11="","",COUNTIF(Funções!C$8:C$522,D11)) | F11: =SUMIF(Funções!$C$8:$C$522,Deflatores!G5,Funções!$H$8:$H$522) | G11: =IF(ISBLANK(Deflatores!H5),"",Deflatores!H5) | H11: =IF(ISBLANK(Deflatores!I5),"",Deflatores!I5) | I11: =IF(F11=0,Deflatores!K5,F11*G11) | J11: =IF($L$11<>0,I11/$L$11,"") | L11: =Contagem!Q6
B12: =""&Deflatores!B6 | D12: =""&Deflatores!G6 | E12: =IF(D12="","",COUNTIF(Funções!C$8:C$522,D12)) | F12: =SUMIF(Funções!$C$8:$C$522,Deflatores!G6,Funções!$H$8:$H$522) | G12: =IF(ISBLANK(Deflatores!H6),"",Deflatores!H6) | H12: =IF(ISBLANK(Deflatores!I6),"",Deflatores!I6) | I12: =IF(F12=0,Deflatores!K6,F12*G12) | J12: =IF($L$11<>0,I12/$L$11,"")
B13: =""&Deflatores!B7 | D13: =""&Deflatores!G7 | E13: =IF(D13="","",COUNTIF(Funções!C$8:C$522,D13)) | F13: =SUMIF(Funções!$C$8:$C$522,Deflatores!G7,Funções!$H$8:$H$522) | G13: =IF(ISBLANK(Deflatores!H7),"",Deflatores!H7) | H13: =IF(ISBLANK(Deflatores!I7),"",Deflatores!I7) | I13: =Deflatores!K7 | J13: =IF($L$11<>0,I13/$L$11,"") | L13: Total IFPUG
B14: =""&Deflatores!B8 | D14: =""&Deflatores!G8 | E14: =IF(D14="","",COUNTIF(Funções!C$8:C$522,D14)) | F14: =SUMIF(Funções!$C$8:$C$522,Deflatores!G8,Funções!$H$8:$H$522) | G14: =IF(ISBLANK(Deflatores!H8),"",Deflatores!H8) | H14: =IF(ISBLANK(Deflatores!I8),"",Deflatores!I8) | I14: =Deflatores!K8 | J14: =IF($L$11<>0,I14/$L$11,"") | L14: =Contagem!Q4
B15: =""&Deflatores!B9 | D15: =""&Deflatores!G9 | E15: =IF(D15="","",COUNTIF(Funções!C$8:C$522,D15)) | F15: =SUMIF(Funções!$C$8:$C$522,Deflatores!G9,Funções!$H$8:$H$522) | G15: =IF(ISBLANK(Deflatores!H9),"",Deflatores!H9) | H15: =IF(ISBLANK(Deflatores!I9),"",Deflatores!I9) | I15: =Deflatores!K9 | J15: =IF($L$11<>0,I15/$L$11,"")
B16: =""&Deflatores!B10 | D16: =""&Deflatores!G10 | E16: =IF(D16="","",COUNTIF(Funções!C$8:C$522,D16)) | F16: =SUMIF(Funções!$C$8:$C$522,Deflatores!G10,Funções!$H$8:$H$522) | G16: =IF(ISBLANK(Deflatores!H10),"",Deflatores!H10) | H16: =IF(ISBLANK(Deflatores!I10),"",Deflatores!I10) | I16: =Deflatores!K10 | J16: =IF($L$11<>0,I16/$L$11,"")
B17: =""&Deflatores!B11 | D17: =""&Deflatores!G11 | E17: =IF(D17="","",COUNTIF(Funções!C$8:C$522,D17)) | F17: =SUMIF(Funções!$C$8:$C$522,Deflatores!G11,Funções!$H$8:$H$522) | G17: =IF(ISBLANK(Deflatores!H11),"",Deflatores!H11) | H17: =IF(ISBLANK(Deflatores!I11),"",Deflatores!I11) | I17: =Deflatores!K11 | J17: =IF($L$11<>0,I17/$L$11,"")
B18: =""&Deflatores!B12 | D18: =""&Deflatores!G12 | E18: =IF(D18="","",COUNTIF(Funções!C$8:C$522,D18)) | F18: =SUMIF(Funções!$C$8:$C$522,Deflatores!G12,Funções!$H$8:$H$522) | G18: =IF(ISBLANK(Deflatores!H12),"",Deflatores!H12) | H18: =IF(ISBLANK(Deflatores!I12),"",Deflatores!I12) | I18: =Deflatores!K12 | J18: =IF($L$11<>0,I18/$L$11,"")
B19: =""&Deflatores!B13 | D19: =""&Deflatores!G13 | E19: =IF(D19="","",COUNTIF(Funções!C$8:C$522,D19)) | F19: =SUMIF(Funções!$C$8:$C$522,Deflatores!G13,Funções!$H$8:$H$522) | G19: =IF(ISBLANK(Deflatores!H13),"",Deflatores!H13) | H19: =IF(ISBLANK(Deflatores!I13),"",Deflatores!I13) | I19: =Deflatores!K13 | J19: =IF($L$11<>0,I19/$L$11,"")
B20: =""&Deflatores!B14 | D20: =""&Deflatores!G14 | E20: =IF(D20="","",COUNTIF(Funções!C$8:C$522,D20)) | F20: =SUMIF(Funções!$C$8:$C$522,Deflatores!G14,Funções!$H$8:$H$522) | G20: =IF(ISBLANK(Deflatores!H14),"",Deflatores!H14) | H20: =IF(ISBLANK(Deflatores!I14),"",Deflatores!I14) | I20: =Deflatores!K14 | J20: =IF($L$11<>0,I20/$L$11,"")
B21: =""&Deflatores!B15 | D21: =""&Deflatores!G15 | E21: =IF(D21="","",COUNTIF(Funções!C$8:C$522,D21)) | F21: =SUMIF(Funções!$C$8:$C$522,Deflatores!G15,Funções!$H$8:$H$522) | G21: =IF(ISBLANK(Deflatores!H15),"",Deflatores!H15) | H21: =IF(ISBLANK(Deflatores!I15),"",Deflatores!I15) | I21: =Deflatores!K15 | J21: =IF($L$11<>0,I21/$L$11,"")
B22: =""&Deflatores!B16 | D22: =""&Deflatores!G16 | E22: =IF(D22="","",COUNTIF(Funções!C$8:C$522,D22)) | F22: =SUMIF(Funções!$C$8:$C$522,Deflatores!G16,Funções!$H$8:$H$522) | G22: =IF(ISBLANK(Deflatores!H16),"",Deflatores!H16) | H22: =IF(ISBLANK(Deflatores!I16),"",Deflatores!I16) | I22: =Deflatores!K16 | J22: =IF($L$11<>0,I22/$L$11,"")
B23: =""&Deflatores!B17 | D23: =""&Deflatores!G17 | E23: =IF(D23="","",COUNTIF(Funções!C$8:C$522,D23)) | F23: =SUMIF(Funções!$C$8:$C$522,Deflatores!G17,Funções!$H$8:$H$522) | G23: =IF(ISBLANK(Deflatores!H17),"",Deflatores!H17) | H23: =IF(ISBLANK(Deflatores!I17),"",Deflatores!I17) | I23: =Deflatores!K17 | J23: =IF($L$11<>0,I23/$L$11,"")
B24: =""&Deflatores!B18 | D24: =""&Deflatores!G18 | E24: =IF(D24="","",COUNTIF(Funções!C$8:C$522,D24)) | F24: =SUMIF(Funções!$C$8:$C$522,Deflatores!G18,Funções!$H$8:$H$522) | G24: =IF(ISBLANK(Deflatores!H18),"",Deflatores!H18) | H24: =IF(ISBLANK(Deflatores!I18),"",Deflatores!I18) | I24: =Deflatores!K18 | J24: =IF($L$11<>0,I24/$L$11,"")
B25: =""&Deflatores!B19 | D25: =""&Deflatores!G19 | E25: =IF(D25="","",COUNTIF(Funções!C$8:C$522,D25)) | F25: =SUMIF(Funções!$C$8:$C$522,Deflatores!G19,Funções!$H$8:$H$522) | G25: =IF(ISBLANK(Deflatores!H19),"",Deflatores!H19) | H25: =IF(ISBLANK(Deflatores!I19),"",Deflatores!I19) | I25: =Deflatores!K19 | J25: =IF($L$11<>0,I25/$L$11,"")
B26: =""&Deflatores!B20 | D26: =""&Deflatores!G20 | E26: =IF(D26="","",COUNTIF(Funções!C$8:C$522,D26)) | F26: =SUMIF(Funções!$C$8:$C$522,Deflatores!G20,Funções!$H$8:$H$522) | G26: =IF(ISBLANK(Deflatores!H20),"",Deflatores!H20) | H26: =IF(ISBLANK(Deflatores!I20),"",Deflatores!I20) | I26: =Deflatores!K20 | J26: =IF($L$11<>0,I26/$L$11,"")
... B44: =""&Deflatores!B38 | D44: =""&Deflatores!G38 | E44: =IF(D44="","",COUNTIF(Funções!C$8:C$522,D44)) | F44: =SUMIF(Funções!$C$8:$C$522,Deflatores!G38,Funções!$H$8:$H$522) | G44: =IF(ISBLANK(Deflatores!H38),"",Deflatores!H38) | H44: =IF(ISBLANK(Deflatores!I38),"",Deflatores!I38) | I44: =Deflatores!K38 | J44: =IF($L$11<>0,I44/$L$11,"")
B46: Itens não Funcionais (Tipo de Função) | E46: Quantidade | H46: Contrib. Fixa | I46: PF Local da FS | J46: % LOCAL
B47: =""&Deflatores!B42 | D47: =""&Deflatores!G42 | E47: =Deflatores!J42 | H47: =IF(ISBLANK(Deflatores!H42),"",Deflatores!H42) | I47: =IF(ISNUMBER(H47),E47*H47,"") | J47: =IF(ISNUMBER(I47),IF($L$11<>0,I47/$L$11,""),"")
B48: =""&Deflatores!B43 | D48: =""&Deflatores!G43 | E48: =Deflatores!J43 | H48: =IF(ISBLANK(Deflatores!H43),"",Deflatores!H43) | I48: =IF(ISNUMBER(H48),E48*H48,"") | J48: =IF(ISNUMBER(I48),IF($L$11<>0,I48/$L$11,""),"")
B49: =""&Deflatores!B44 | D49: =""&Deflatores!G44 | E49: =Deflatores!J44 | H49: =IF(ISBLANK(Deflatores!H44),"",Deflatores!H44) | I49: =IF(ISNUMBER(H49),E49*H49,"") | J49: =IF(ISNUMBER(I49),IF($L$11<>0,I49/$L$11,""),"")
B50: =""&Deflatores!B45 | D50: =""&Deflatores!G45 | E50: =Deflatores!J45 | H50: =IF(ISBLANK(Deflatores!H45),"",Deflatores!H45) | I50: =IF(ISNUMBER(H50),E50*H50,"") | J50: =IF(ISNUMBER(I50),IF($L$11<>0,I50/$L$11,""),"")
B51: =""&Deflatores!B46 | D51: =""&Deflatores!G46 | E51: =Deflatores!J46 | H51: =IF(ISBLANK(Deflatores!H46),"",Deflatores!H46) | I51: =IF(ISNUMBER(H51),E51*H51,"") | J51: =IF(ISNUMBER(I51),IF($L$11<>0,I51/$L$11,""),"")
B52: =""&Deflatores!B47 | D52: =""&Deflatores!G47 | E52: =Deflatores!J47 | H52: =IF(ISBLANK(Deflatores!H47),"",Deflatores!H47) | I52: =IF(ISNUMBER(H52),E52*H52,"") | J52: =IF(ISNUMBER(I52),IF($L$11<>0,I52/$L$11,""),"")
B53: =""&Deflatores!B48 | D53: =""&Deflatores!G48 | E53: =Deflatores!J48 | H53: =IF(ISBLANK(Deflatores!H48),"",Deflatores!H48) | I53: =IF(ISNUMBER(H53),E53*H53,"") | J53: =IF(ISNUMBER(I53),IF($L$11<>0,I53/$L$11,""),"")
B54: =""&Deflatores!B49 | D54: =""&Deflatores!G49 | E54: =Deflatores!J49 | H54: =IF(ISBLANK(Deflatores!H49),"",Deflatores!H49) | I54: =IF(ISNUMBER(H54),E54*H54,"") | J54: =IF(ISNUMBER(I54),IF($L$11<>0,I54/$L$11,""),"")
B55: =""&Deflatores!B50 | D55: =""&Deflatores!G50 | E55: =Deflatores!J50 | H55: =IF(ISBLANK(Deflatores!H50),"",Deflatores!H50) | I55: =IF(ISNUMBER(H55),E55*H55,"") | J55: =IF(ISNUMBER(I55),IF($L$11<>0,I55/$L$11,""),"")
B56: =""&Deflatores!B51 | D56: =""&Deflatores!G51 | E56: =Deflatores!J51 | H56: =IF(ISBLANK(Deflatores!H51),"",Deflatores!H51) | I56: =IF(ISNUMBER(H56),E56*H56,"") | J56: =IF(ISNUMBER(I56),IF($L$11<>0,I56/$L$11,""),"")
B57: =""&Deflatores!B52 | D57: =""&Deflatores!G52 | E57: =Deflatores!J52 | H57: =IF(ISBLANK(Deflatores!H52),"",Deflatores!H52) | I57: =IF(ISNUMBER(H57),E57*H57,"") | J57: =IF(ISNUMBER(I57),IF($L$11<>0,I57/$L$11,""),"")
B58: =""&Deflatores!B53 | D58: =""&Deflatores!G53 | E58: =Deflatores!J53 | H58: =IF(ISBLANK(Deflatores!H53),"",Deflatores!H53) | I58: =IF(ISNUMBER(H58),E58*H58,"") | J58: =IF(ISNUMBER(I58),IF($L$11<>0,I58/$L$11,""),"")
... B69: =""&Deflatores!B64 | D69: =""&Deflatores!G64 | E69: =Deflatores!J64 | H69: =IF(ISBLANK(Deflatores!H64),"",Deflatores!H64) | I69: =IF(ISNUMBER(H69),E69*H69,"") | J69: =IF(ISNUMBER(I69),IF($L$11<>0,I69/$L$11,""),"")
